Workbook

Sheet DCF Fill in 
B2: Unlevered Free Cash Flow (mm)
B3: Fiscal Year | D3: 43830 | E3: 44196 | F3: 44561 | G3: 44926 | H3: 45291 | I3: 45657 | J3: 46022 | K3: 46387
B4: Unlevered Free Cash Flow | D4: 978 | E4: 523 | F4: 1913 | G4: ='1)FCF'!F21 -> 5395.5859 | H4: ='1)FCF'!G21 -> 4558.5357 | I4: ='1)FCF'!H21 -> 4496.1347 | J4: ='1)FCF'!I21 -> 4834.7255 | K4: ='1)FCF'!J21 -> 5160.805
B6: Projection Year | G6: 1 | H6: 2 | I6: 3 | J6: 4 | K6: 5
B7: Present Value of Free Cash Flow | G7: =G4/(1+$C$12)^G6 -> 4966.272 | H7: =H4/(1+$C$12)^H6 -> 3861.9721 | I7: =I4/(1+$C$12)^I6 -> 3506.0248 | J7: =J4/(1+$C$12)^J6 -> 3470.0791 | K7: =K4/(1+$C$12)^K6 -> 3409.3916
B9: Implied Share Price Calculation | E9: Sensitivity Table
B10: Sum of PV of FCF | C10: =SUM(G7:K7) -> 19213.74
B11: Growth Rate | C11: 0.03 | G11: Growth Rate
B12: WACC | C12: ='2)WACC'!C19 -> 0.086445917 | F12: =C21 -> 204.56537 | G12: =H12-0.5% -> 0.02 | H12: =I12-0.5% -> 0.025 | I12: 0.03 | J12: =I12+0.5% -> 0.035 | K12: =J12+0.5% -> 0.04
B13: Terminal Value | C13: =K4*(1+C11)/(C12-C11) -> 94172.076 | E13: WACC | F13: =F14-0.5% -> 0.076445917 | G13: 210.91239 | H13: 225.80648 | I13: 243.90732 | J13: 266.37551 | K13: 295.0085
B14: PV of Terminal Value | C14: =C13/(1+C12)^K6 -> 62213.063 | F14: =F15-0.5% -> 0.081445917 | G14: 195.46206 | H14: 207.70319 | I14: 222.32373 | J14: 240.09214 | K14: 262.14768
B15: Enterprise Value | C15: =C14+C10 -> 81426.803 | F15: 0.086445917 | G15: 182.33929 | H15: 192.54803 | I15: 204.56537 | J15: 218.91862 | K15: 236.36218
B16: (+) Cash | C16: =BS!B2 -> 15284 | F16: =F15+0.5% -> 0.091445917 | G16: 171.05532 | H16: 179.6754 | I16: 189.69836 | J16: 201.497 | K16: 215.58904
B17: (-) Debt | C17: =BS!B17+BS!B21 -> 5813 | F17: =F16+0.5% -> 0.096445917 | G17: 161.24929 | H17: 168.60603 | I17: 177.06996 | J17: 186.91134 | K17: 198.49622
B18: (-) Minority Interest | C18: 0
B19: Equity Value | C19: =C15+C16-C17-C18 -> 90897.803
B20: Diluted Shares Outstanding (mm) | C20: 444.346
B21: Implied Share Price | C21: =C19/C20 -> 204.56537
M35: +

Sheet 1)FCF
B2: Unlevered Free Cash Flow (mm) | O2: Fixed Assets Schedule
B3: Fiscal Year | C3: 43466 | D3: 43832 | E3: 44199 | F3: 44756 | G3: 45122 | H3: 45489 | I3: 45855 | J3: 45855 | O3: Fiscal Year | P3: 43830 | Q3: 44196 | R3: 44561 | S3: 44926 | T3: 45291 | U3: 45657 | V3: 46022 | W3: 46387
B4: Revenue | C4: 152703 | D4: 166761 | E4: 195929 | F4: =E4*(1+F25) -> 226954 | G4: =F4*(1+G25) -> 242290 | H4: =G4*(1+H25) -> 254453 | I4: =H4*(1+I25) -> 275235 | J4: =I4*(1+J25) -> 293533.23 | K4: (1+x) | O4: Beginning PP&E | P4: 21807 | Q4: 21807 | R4: 23614 | S4: =R7 -> 25421 | T4: =S7 -> 27253.854 | U4: =T7 -> 29235.209 | V4: =U7 -> 31372.303 | W4: =V7 -> 33988.753
B5: COGS | C5: 132886 | D5: 144939 | E5: 170684 | F5: =F4*F27 -> 197501.09 | G5: =G4*G27 -> 210846.87 | H5: =H4*H27 -> 221431.41 | I5: =I4*I27 -> 239516.44 | J5: =J4*J27 -> 255440.01 | K5: (z*x) | O5: (-)D&A | P5: -1492 | Q5: =-1645 -> -1645 | R5: =-1781 -> -1781 | S5: =S4*S12 -> 2056.5589 | T5: =T4*T12 -> 2297.4999 | U5: =U4*U12 -> 2452.8341 | V5: =V4*V12 -> 2622.7245 | W5: =W4*W12 -> 2852.7893 | X5: D&A=Beginning PP&E×D&A %
B6: Gross Profit | C6: =C4-C5 -> 19817 | D6: =D4-D5 -> 21822 | E6: =E4-E5 -> 25245 | F6: =F4-F5 -> 29452.908 | G6: =G4-G5 -> 31443.134 | H6: =H4-H5 -> 33021.585 | I6: =I4-I5 -> 35718.565 | J6: =J4-J5 -> 38093.213 | O6: (+)CapEx | P6: 2998 | Q6: 2810 | R6: 3588 | S6: =S4*S13 -> 3889.413 | T6: =T4*T13 -> 4278.8551 | U6: =U4*U13 -> 4589.9279 | V6: =V4*V13 -> 5239.1746 | W6: =W4*W13 -> 5449.5301
B7: Operating Expenses | C7: 15800 | D7: 14994 | E7: 18537 | O7: Ending PP&E | P7: =P4+P5+P6 -> 23313 | Q7: =Q4+Q5+Q6 -> 22972 | R7: =R4+R5+R6 -> 25421 | S7: =S4-S5+S6 -> 27253.854 | T7: =T4-T5+T6 -> 29235.209 | U7: =U4-U5+U6 -> 31372.303 | V7: =V4-V5+V6 -> 33988.753 | W7: =W4-W5+W6 -> 36585.494
B8: Selling, General, Administrative | C8: 14994 | D8: 16387 | E8: 18537 | F8: =F4*F28 -> 19779 | G8: =G4*G28 -> 21115.53 | H8: =H4*H28 -> 22673.822 | I8: =I4*I28 -> 24672.967 | J8: =J4*J28 -> 26625.794 | K8: rev *x
B9: Total Operating Expenses | C9: =C8 -> 14994 | D9: =D8 -> 16387 | E9: =E8 -> 18537 | F9: =F8 -> 19779 | G9: =G8 -> 21115.53 | H9: =H8 -> 22673.822 | I9: =I8 -> 24672.967 | J9: =J8 -> 26625.794 | K9: only have 1 so just sga
A10: X | B10: EBITDA | C10: =C11+C12 -> 6315 | D10: =D11+D12 -> 7080 | E10: =E11+E12 -> 8489 | F10: =F6-F9 -> 9673.9081 | G10: =G6-G9 -> 10327.605 | H10: =H6-H9 -> 10347.763 | I10: =I6-I9 -> 11045.598 | J10: =J6-J9 -> 11467.419 | K10: GP - total expenses | O10: Assumptions
B11: Depreciation & Amortization | C11: 1492 | D11: 1645 | E11: 1781 | F11: =S5 -> 2056.5589 | G11: =T5 -> 2297.4999 | H11: =U5 -> 2452.8341 | I11: =V5 -> 2622.7245 | J11: =W5 -> 2852.7893 | O11: Fiscal Year | P11: 43830 | Q11: 44196 | R11: 44561 | S11: 44926 | T11: 45291 | U11: 45657 | V11: 46022 | W11: 46387
B12: Operating Profit (EBIT)( work before ebitda) | C12: =C6-C8 -> 4823 | D12: =D6-D8 -> 5435 | E12: =E6-E8 -> 6708 | F12: =F10-F11 -> 7617.3492 | G12: =G10-G11 -> 8030.1047 | H12: =H10-H11 -> 7894.9292 | I12: =I10-I11 -> 8422.8737 | J12: =J10-J11 -> 8614.6295 | O12: D&A as a % of Beginning PP&E | P12: 0.0684 | Q12: 0.0755 | R12: 0.0675 | S12: 0.0809 | T12: 0.0843 | U12: 0.0839 | V12: 0.0836 | W12: =AVERAGE(T12:V12) -> 0.083933333
B13: Operating Taxes | C13: 1061 | D13: 1308 | E13: 1601 | F13: =F12*F29 -> 1873.8679 | G13: =G12*G29 -> 2079.7971 | H13: =H12*H29 -> 1926.3627 | I13: =I12*I29 -> 2114.1413 | J13: =J12*J29 -> 2165.1435 | O13: CapEx as a % of Beginning PP&E | P13: 0.1375 | Q13: 0.1191 | R13: 0.152 | S13: 0.153 | T13: 0.157 | U13: 0.157 | V13: 0.167 | W13: =AVERAGE(T13:V13) -> 0.16033333
B14: NOPAT (Net Operating Profit After Taxes) | C14: =C12*(1-C29) -> 3747.471 | D14: =D12*(1-D29) -> 4125.165 | E14: =E12*(1-E29) -> 5098.08 | F14: =F12-F13 -> 5743.4813 | G14: =G12-G13 -> 5950.3076 | H14: =H12-H13 -> 5968.5665 | I14: =I12-I13 -> 6308.7324 | J14: =J12-J13 -> 6449.4859
B15: (+) Depreciation & Amortization | C15: 1492 | D15: 1645 | E15: 1781 | F15: =S5 -> 2056.5589 | G15: =T5 -> 2297.4999 | H15: =U5 -> 2452.8341 | I15: =V5 -> 2622.7245 | J15: =W5 -> 2852.7893
B16: (-) Capital Expenditures(buying factory,outflow) | C16: =-2998 -> -2998 | D16: =-2810 -> -2810 | E16: =-3588 -> -3588 | F16: =-S6 -> -3889.413 | G16: =-T6 -> -4278.8551 | H16: =-U6 -> -4589.9279 | I16: =-V6 -> -5239.1746 | J16: =-W6 -> -5449.5301 | O16: D&A as a % of Beginning PP&E | P16: grab from 10k cfs
B17: (+/-) Change in NWC (depends on assets) | C17: -1263 | D17: =D18-C18 -> -2437 | E17: =E18-D18 -> -1378 | F17: =F18-E18 -> -1484.9588 | G17: =G18-F18 -> -589.58327 | H17: =H18-G18 -> -664.66203 | I17: =I18-H18 -> -1142.4432 | J17: =J18-I18 -> -1308.0598 | O17: CapEx as a % of Beginning PP&E | P17: grab from 10k stmtn
B18: NWC(ca-cl) | C18: -7497 | D18: -9934 | E18: -11312 | F18: =F19-F20 -> -12796.959 | G18: =G19-G20 -> -13386.542 | H18: =H19-H20 -> -14051.204 | I18: =I19-I20 -> -15193.647 | J18: =J19-J20 -> -16501.707
B19: Current Assets | C19: 14041 | D19: 14815 | E19: 17330 | F19: =T29 -> 20415.163 | G19: =U29 -> 21772.05 | H19: =V29 -> 22789.273 | I19: =W29 -> 24597.295 | J19: =X29 -> 26681.675
B20: Current Liabilitites | C20: 21538 | D20: 24749 | E20: 28642 | F20: =T36 -> 33212.122 | G20: =U36 -> 35158.592 | H20: =V36 -> 36840.477 | I20: =W36 -> 39790.942 | J20: =X36 -> 43183.382
A21: X | B21: Unlevered Free Cash Flow | C21: =C12*(1-C29)+C15+C16+C17 -> 978.471 | D21: =D12*(1-D29)+D15+D16+D17 -> 523.165 | E21: =E12*(1-E29)+E15+E16+E17 -> 1913.08 | F21: =F14+F15+F16-F17 -> 5395.5859 | G21: =G14+G15+G16-G17 -> 4558.5357 | H21: =H14+H15+H16-H17 -> 4496.1347 | I21: =I14+I15+I16-I17 -> 4834.7255 | J21: =J14+J15+J16-J17 -> 5160.805
B23: Assumptions
B24: =B3 -> Fiscal Year | C24: 43466 | D24: 43832 | E24: 44199 | F24: 44756 | G24: 45122 | H24: 45489 | I24: 45855 | J24: 46220 | O24: Net working capital
B25: Revenue Growth | C25: =(152703-141576)/141576 -> 0.078593829 | D25: =(166761-152703)/152703 -> 0.09206106 | E25: =(195929-166761)/166761 -> 0.174909 | F25: =(226954-195929)/195929 -> 0.15834818 | G25: =(242290-226954)/226954 -> 0.067573165 | H25: =(254453-242290)/242290 -> 0.050200173 | I25: =(275235-254453)/254453 -> 0.081673236 | J25: =AVERAGE(G25:I25) -> 0.066482191 | O25: Fiscal Year | P25: 2018A | Q25: 2019A | R25: 2020A | S25: 2021A | T25: 2022E | U25: 2023E | V25: 2024E | W25: 2025E | X25: 2026E
O26: Accounts Receivables | P26: 2241 | Q26: 1535 | R26: 1550 | S26: 1803 | T26: =T43*T40/365 -> 2114.0921 | U26: =U43*U40/365 -> 2256.9479 | V26: =V43*V40/365 -> 2370.2471 | W26: =W43*W40/365 -> 2563.8329 | X26: =X43*X40/365 -> 2785.2055
B27: COGS % of Revenue | C27: =132886/152703 -> 0.87022521 | D27: =AVERAGE(C27:C27) -> 0.87022521 | E27: =AVERAGE(C27:D27) -> 0.87022521 | F27: =AVERAGE(C27:E27) -> 0.87022521 | G27: =AVERAGE(D27:F27) -> 0.87022521 | H27: =AVERAGE(E27:G27) -> 0.87022521 | I27: =AVERAGE(F27:H27) -> 0.87022521 | J27: =AVERAGE(G27:I27) -> 0.87022521 | O27: Merchandise Inventory | P27: 11040 | Q27: 11395 | R27: 12242 | S27: 14215 | T27: =T44*T41/360 -> 16781.318 | U27: =U44*U41/360 -> 17892.655 | V27: =V44*V41/360 -> 18715.132 | W27: =W44*W41/360 -> 20190.405 | X27: =X44*X41/360 -> 21894.275
B28: SG&A % of Revenue | C28: =14994/152703 -> 0.098190605 | D28: =16387/166761 -> 0.098266381 | E28: =18537/195929 -> 0.094610803 | F28: =19779/226954 -> 0.087149819 | G28: =19779/226954 -> 0.087149819 | H28: =21590/242290 -> 0.089108094 | I28: =22810/254453 -> 0.089643274 | J28: =24966/275235 -> 0.09070794 | O28: Other Current Assets | P28: 321 | Q28: 1111 | R28: 1023 | S28: 1312 | T28: =T47*T40 -> 1519.7528 | U28: =U47*U40 -> 1622.4473 | V28: =V47*V40 -> 1703.8945 | W28: =W47*W40 -> 1843.057 | X28: =X47*X40 -> 2002.1947
B29: Tax % of EBIT | C29: 0.223 | D29: 0.241 | E29: 0.24 | F29: 0.246 | G29: 0.259 | H29: 0.244 | I29: 0.251 | J29: =AVERAGE(G29:I29) -> 0.25133333 | O29: Current Assets | P29: 20289 | Q29: 23485 | R29: 28120 | S29: 29505 | T29: =SUM(T26:T28) -> 20415.163 | U29: =SUM(U26:U28) -> 21772.05 | V29: =SUM(V26:V28) -> 22789.273 | W29: =SUM(W26:W28) -> 24597.295 | X29: =SUM(X26:X28) -> 26681.675
O31: Accounts Payable | P31: 11237 | Q31: 11679 | R31: 14172 | S31: 16278 | T31: =T45*T41/360 -> 18664.371 | U31: =U45*U41/365 -> 19627.803 | V31: =V45*V41/365 -> 20530.04 | W31: =W45*W41/365 -> 22148.379 | X31: =X45*X41/365 -> 24017.482
B32: Revenue growth? | C32: pull from 10k net sales + membership fees then do (next yr - prev)/prev | O32: Accrued Salaries and Benefits | P32: 2994 | Q32: 3176 | R32: 3605 | S32: 4090 | T32: =T48*T40 -> 4788.7294 | U32: =U48*U40 -> 5112.319 | V32: =V48*V40 -> 5368.9583 | W32: =W48*W40 -> 5807.4585 | X32: =X48*X40 -> 6308.9
O33: Accrued Member Rewards | P33: 1057 | Q33: 1180 | R33: 1393 | S33: 1671 | T33: =T49*T40 -> 1951.8044 | U33: =U49*U40 -> 2083.694 | V33: =V49*V40 -> 2188.2958 | W33: =W49*W40 -> 2367.021 | X33: =X49*X40 -> 2571.4
B34: COGS % of Revenue? | C34: Pull Cogs(merchandise costs-direct cost so exclude sg&A) from 10k / total rev | O34: Deferred Membership Fees | P34: 1624 | Q34: 1711 | R34: 1851 | S34: 2042 | T34: =T50*T40 -> 2473.7986 | U34: =U50*U40 -> 2640.961 | V34: =V50*V40 -> 2773.5377 | W34: =W50*W40 -> 3000.0615 | X34: =X50*X40 -> 3259.1
B35: SG&A % of Revenue? | C35: PULL SG&A costs- indirect costs still needded for operating / total rev) | M35: + | O35: Other Current Liabilities | P35: 2924 | Q35: 3792 | R35: 3728 | S35: 4561 | T35: =T51*T40 -> 5333.419 | U35: =U51*U40 -> 5693.815 | V35: =V51*V40 -> 5979.6455 | W35: =W51*W40 -> 6468.0225 | X35: =X51*X40 -> 7026.5
B36: Tax % of EBIT? | C36: pull from 10k | O36: Current Liabilities | P36: 19836 | Q36: 23237 | R36: 24844 | S36: 29441 | T36: =SUM(T31:T35) -> 33212.122 | U36: =SUM(U31:U35) -> 35158.592 | V36: =SUM(V31:V35) -> 36840.477 | W36: =SUM(W31:W35) -> 39790.942 | X36: =SUM(X31:X35) -> 43183.382
O38: Assumptions
B39: NWC | C39: NWC = AR + Inventory – AP | O39: Fiscal Year | P39: 2018A | Q39: 2019A | R39: 2020A | S39: 2021A | T39: 2022E | U39: 2023E | V39: 2024E | W39: 2025E | X39: 2026E
O40: Revenue | P40: 141576 | Q40: 152703 | R40: 166761 | S40: 195929 | T40: 226954 | U40: 242290 | V40: 254453 | W40: 275235 | X40: 299000
O41: COGS | P41: 123152 | Q41: 132886 | R41: 144939 | S41: 170684 | T41: 199382 | U41: 212586 | V41: 222358 | W41: 239886 | X41: 260130
O43: Days Sales Outstanding (DSO) | P43: =P26/P40*360 -> 5.6984235 | Q43: =Q26/Q40*360 -> 3.6187894 | R43: =R26/R40*360 -> 3.3461061 | S43: =S26/S40*360 -> 3.3128327 | T43: 3.4 | U43: 3.4 | V43: 3.4 | W43: =AVERAGE(T43:V43) -> 3.4 | X43: =AVERAGE(U43:W43) -> 3.4
O44: Days Inventory Outstanding (DIO) | P44: =P27/P41*360 -> 32.272314 | Q44: =Q27/Q41*360 -> 30.870069 | R44: =R27/R41*360 -> 30.406723 | S44: =S27/S41*360 -> 29.981721 | T44: 30.3 | U44: =T44 -> 30.3 | V44: =U44 -> 30.3 | W44: =V44 -> 30.3 | X44: =AVERAGE(U44:W44) -> 30.3
O45: Days Payable Outstanding (DPO) | P45: 32.78 | Q45: =Q31/Q41*360 -> 31.63945 | R45: =R31/R41*360 -> 35.200464 | S45: =S31/S41*360 -> 34.332919 | T45: 33.7 | U45: =T45 -> 33.7 | V45: =U45 -> 33.7 | W45: =V45 -> 33.7 | X45: =W45 -> 33.7
...

Sheet 2)WACC
B3: Weighted Average Cost of Capital (WACC)
B4: Equity (mm) | C4: 465000
B5: Debt (mm) | C5: 8160
B7: Cost of Debt | C7: =-IS!F10/C5 -> 0.016176471
B8: Tax Rate | C8: 0.25
B9: D/(D+E) | C9: =C5/SUM(C4:C5) -> 0.017245752
B10: After Tax Cost of Debt | C10: =C7*(1-C8) -> 0.012132353
B12: Risk Free Rate (10-Yr Treasury Yield) | C12: 0.045
B13: Expected Market Return | C13: 0.09
B14: Market Risk Premium | C14: =C13-C12 -> 0.045
B15: Levered Beta | C15: 0.95
B16: E/(D+E) | C16: =C4/SUM(C4:C5) -> 0.98275425
B17: Cost of Equity | C17: =C12+C15*(C14) -> 0.08775
B19: WACC | C19: =C10*C9+C17*C16 -> 0.086445917

Sheet Data sources

Sheet IS
A1: Item | B1: 2025 | C1: 2024 | D1: 2023 | E1: 2022 | F1: 2021
A2: Net Sales | B2: 269912 | C2: 249625 | D2: 237710 | E2: 222730 | F2: 191714
A3: Membership Fees | B3: 5323 | C3: 4828 | D3: 4580 | E3: 4224 | F3: 4215
A4: Total Revenue | B4: 275235 | C4: 254453 | D4: 242290 | E4: 226954 | F4: 195929
A5: Merchandise Costs | B5: 239886 | C5: 222358 | D5: 212586 | E5: 199382 | F5: 170684
A6: Gross Profit | B6: 35349 | C6: 32095 | D6: 29704 | E6: 27572 | F6: 25245
A7: SG&A | B7: 24966 | C7: 22810 | D7: 21590 | E7: 19779 | F7: 18537
A8: Preopening Expenses (included in SG&A) | B8: 80 | C8: 70 | D8: 65 | E8: 60 | F8: 55
A9: Operating Income | B9: 10383 | C9: 9285 | D9: 8114 | E9: 7793 | F9: 6708
A10: Interest Expense | B10: -154 | C10: -169 | D10: -160 | E10: -172 | F10: -132
A11: Interest Income and Other, net | B11: 589 | C11: 624 | D11: 533 | E11: 219 | F11: 104
A12: Income Before Income Taxes | B12: 10818 | C12: 9740 | D12: 8487 | E12: 7840 | F12: 6680
... A17: Weighted Average Shares - Diluted (M) | B17: 445 | C17: 445 | D17: 445 | E17: 450 | F17: 450

Sheet BS
A1: Item | B1: 2025 | C1: 2024 | D1: 2023 | E1: 2022 | F1: 2021
A2: Cash and Cash Equivalents | B2: 15284 | C2: 11144 | D2: 15234 | E2: 11049 | F2: 12175
A3: Short-term Investments | B3: 0 | C3: 1238 | D3: 1534 | E3: 406 | F3: 406
A4: Receivables, net | B4: 3203 | C4: 2721 | D4: 2285 | E4: 2241 | F4: 1803
A5: Merchandise Inventories | B5: 18116 | C5: 18647 | D5: 16651 | E5: 17907 | F5: 14215
A6: Other Current Assets | B6: 1777 | C6: 1734 | D6: 1709 | E6: 1499 | F6: 1312
A7: **Total Current Assets** | B7: 38380 | C7: 34246 | D7: 35879 | E7: 32696 | F7: 29505
A9: Property & Equipment, net | B9: 31909 | C9: 29032 | D9: 26684 | E9: 24646 | F9: 23492
A10: Operating Lease Right-of-Use Assets | B10: 2700 | C10: 2617 | D10: 2713 | E10: 2800 | F10: 2900
A11: Other Long-Term Assets | B11: 4110 | C11: 3936 | D11: 3718 | E11: 3824 | F11: 3371
A12: **Total Assets** | B12: 77099 | C12: 69831 | D12: 68994 | E12: 64166 | F12: 59268
A14: Accounts Payable | B14: 20000 | C14: 19421 | D14: 17483 | E14: 16000 | F14: 15000
... A27: **Total Liabilities + Equity** | B27: 77099 | C27: 69831 | D27: 68994 | E27: 64166 | F27: 59268

Sheet CFS
A1: Item | B1: 2025 | C1: 2024 | D1: 2023 | E1: 2022 | F1: 2021
A2: Net Income | B2: 8099 | C2: 7367 | D2: 6292 | E2: 5915 | F2: 5079
A4: Depreciation & Amortization | B4: 2426 | C4: 2237 | D4: 2077 | E4: 1900 | F4: 1781
A5: Stock-Based Compensation | B5: 860 | C5: 818 | D5: 774 | E5: 724 | F5: 665
A6: Non-cash Lease Expense | B6: 303 | C6: 315 | D6: 412 | E6: 377 | F6: 350
A7: Other Non-Cash Items | B7: 186 | C7: 306 | D7: -495 | E7: 416 | F7: 430
A9: Changes in Merchandise Inventories | B9: 559 | C9: -2068 | D9: 1228 | E9: -4003 | F9: -1892
A10: Changes in Accounts Payable | B10: 404 | C10: 1938 | D10: -382 | E10: 1891 | F10: 1838
A11: Changes in Other Operating Assets & Liabilities | B11: 801 | C11: 741 | D11: 172 | E11: 549 | F11: 1057
A12: **Net Cash from Operating Activities** | B12: 13335 | C12: 11339 | D12: 11068 | E12: 7392 | F12: 8958
A14: Additions to Property & Equipment | B14: -5498 | C14: -4710 | D14: -4323 | E14: -3891 | F14: -3588
A15: Net Change in Short-term Investments | B15: 113 | C15: 320 | D15: -685 | E15: 24 | F15: 115
... A26: **Net Change in Cash & Equivalents** | B26: 4255 | C26: -3794 | D26: 3497 | E26: -1055 | F26: -1019
